Workbook

Sheet Assumptions
A1: SKU MASTER DATA
A2: Product costs, pricing, and inventory parameters
A4: SKU ID | B4: Product Name | C4: Unit Cost | D4: DTC Price | E4: Wholesale Price | F4: Lead Time (Mo) | G4: Safety Stock | H4: Current Inventory | I4: MOQ
A5: SKU001 | B5: Monarch Steel - Black | C5: 120 | D5: 343.99 | E5: 275 | F5: 3 | G5: 100 | H5: 250 | I5: 50
A6: SKU002 | B6: Monarch Steel - White | C6: 120 | D6: 343.99 | E6: 275 | F6: 3 | G6: 100 | H6: 180 | I6: 50
A7: SKU003 | B7: Monarch Steel - Pink | C7: 120 | D7: 343.99 | E7: 275 | F7: 3 | G7: 80 | H7: 150 | I7: 50
A8: SKU004 | B8: Monarch Steel - Blue | C8: 120 | D8: 343.99 | E8: 275 | F8: 3 | G8: 80 | H8: 120 | I8: 50
A9: SKU005 | B9: Monarch Midnight - Black | C9: 125 | D9: 343.99 | E9: 280 | F9: 3 | G9: 80 | H9: 110 | I9: 50
A10: SKU006 | B10: Monarch Midnight - White | C10: 125 | D10: 343.99 | E10: 280 | F10: 3 | G10: 70 | H10: 90 | I10: 50
A11: SKU007 | B11: Ball Markr Tool | C11: 3.5 | D11: 8.99 | E11: 6.5 | F11: 2 | G11: 500 | H11: 800 | I11: 200
A12: SKU008 | B12: Gate Trainr | C12: 4 | D12: 8.99 | E12: 6.5 | F12: 2 | G12: 400 | H12: 600 | I12: 200
A13: SKU009 | B13: Blade Headcover | C13: 8 | D13: 19.99 | E13: 14 | F13: 2 | G13: 200 | H13: 350 | I13: 100
A14: SKU010 | B14: Accessories Bundle | C14: 25 | D14: 49.99 | E14: 35 | F14: 2 | G14: 150 | H14: 300 | I14: 75
A16: 📋 DEFINITIONS
A17: • Unit Cost = Manufacturing cost per item (COGS)
A18: • Lead Time = Months from order placement to warehouse arrival
A19: • Safety Stock = Minimum inventory before triggering reorder alert
A20: • MOQ = Minimum order quantity required by manufacturer

Sheet Demand Forecast
A1: DEMAND FORECAST
A2: 12-month sales projections by channel
A4: DTC / ONLINE SALES
A5: SKU | B5: Channel | C5: January | D5: February | E5: March | F5: April | G5: May | H5: June | I5: July | J5: August | K5: September | L5: October | M5: November | N5: December
A6: SKU001 | B6: DTC | C6: 15 | D6: 18 | E6: 20 | F6: 22 | G6: 25 | H6: 28 | I6: 30 | J6: 32 | K6: 35 | L6: 38 | M6: 40 | N6: 45
A7: SKU002 | B7: DTC | C7: 12 | D7: 14 | E7: 16 | F7: 18 | G7: 20 | H7: 22 | I7: 24 | J7: 26 | K7: 28 | L7: 30 | M7: 32 | N7: 35
A8: SKU003 | B8: DTC | C8: 10 | D8: 12 | E8: 14 | F8: 15 | G8: 17 | H8: 19 | I8: 21 | J8: 23 | K8: 25 | L8: 27 | M8: 29 | N8: 32
A9: SKU004 | B9: DTC | C9: 8 | D9: 10 | E9: 11 | F9: 13 | G9: 15 | H9: 17 | I9: 19 | J9: 21 | K9: 23 | L9: 25 | M9: 27 | N9: 30
A10: SKU005 | B10: DTC | C10: 7 | D10: 9 | E10: 10 | F10: 12 | G10: 14 | H10: 16 | I10: 18 | J10: 20 | K10: 22 | L10: 24 | M10: 26 | N10: 28
A11: SKU006 | B11: DTC | C11: 6 | D11: 8 | E11: 9 | F11: 11 | G11: 13 | H11: 15 | I11: 17 | J11: 19 | K11: 21 | L11: 23 | M11: 25 | N11: 27
A12: SKU007 | B12: DTC | C12: 50 | D12: 55 | E12: 60 | F12: 65 | G12: 70 | H12: 75 | I12: 80 | J12: 85 | K12: 90 | L12: 95 | M12: 100 | N12: 110
A13: SKU008 | B13: DTC | C13: 40 | D13: 45 | E13: 50 | F13: 55 | G13: 60 | H13: 65 | I13: 70 | J13: 75 | K13: 80 | L13: 85 | M13: 90 | N13: 95
A14: SKU009 | B14: DTC | C14: 30 | D14: 35 | E14: 40 | F14: 45 | G14: 50 | H14: 55 | I14: 60 | J14: 65 | K14: 70 | L14: 75 | M14: 80 | N14: 85
A15: SKU010 | B15: DTC | C15: 25 | D15: 28 | E15: 30 | F15: 33 | G15: 36 | H15: 40 | I15: 44 | J15: 48 | K15: 52 | L15: 56 | M15: 60 | N15: 65
A16: RETAIL / WHOLESALE ORDERS
A17: SKU | B17: Channel | C17: January | D17: February | E17: March | F17: April | G17: May | H17: June | I17: July | J17: August | K17: September | L17: October | M17: November | N17: December
A18: SKU001 | B18: Company X | C18: 0 | D18: 0 | E18: 150 | F18: 0 | G18: 0 | H18: 0 | I18: 200 | J18: 0 | K18: 0 | L18: 0 | M18: 250 | N18: 0
A19: SKU001 | B19: Company Y | C19: 0 | D19: 100 | E19: 0 | F19: 0 | G19: 0 | H19: 150 | I19: 0 | J19: 0 | K19: 0 | L19: 200 | M19: 0 | N19: 0
A20: SKU002 | B20: Company X | C20: 0 | D20: 0 | E20: 100 | F20: 0 | G20: 0 | H20: 0 | I20: 150 | J20: 0 | K20: 0 | L20: 0 | M20: 200 | N20: 0
A21: SKU002 | B21: Company Y | C21: 0 | D21: 75 | E21: 0 | F21: 0 | G21: 0 | H21: 100 | I21: 0 | J21: 0 | K21: 0 | L21: 125 | M21: 0 | N21: 0
A22: SKU003 | B22: Company X | C22: 0 | D22: 0 | E22: 80 | F22: 0 | G22: 0 | H22: 0 | I22: 120 | J22: 0 | K22: 0 | L22: 0 | M22: 150 | N22: 0
A23: SKU003 | B23: Company Y | C23: 0 | D23: 60 | E23: 0 | F23: 0 | G23: 0 | H23: 80 | I23: 0 | J23: 0 | K23: 0 | L23: 100 | M23: 0 | N23: 0
A24: SKU004 | B24: Company X | C24: 0 | D24: 0 | E24: 50 | F24: 0 | G24: 0 | H24: 0 | I24: 80 | J24: 0 | K24: 0 | L24: 0 | M24: 100 | N24: 0
A25: SKU004 | B25: Company Y | C25: 0 | D25: 40 | E25: 0 | F25: 0 | G25: 0 | H25: 60 | I25: 0 | J25: 0 | K25: 0 | L25: 75 | M25: 0 | N25: 0
A26: SKU005 | B26: Company X | C26: 0 | D26: 0 | E26: 40 | F26: 0 | G26: 0 | H26: 0 | I26: 70 | J26: 0 | K26: 0 | L26: 0 | M26: 90 | N26: 0
A27: SKU005 | B27: Company Y | C27: 0 | D27: 35 | E27: 0 | F27: 0 | G27: 0 | H27: 55 | I27: 0 | J27: 0 | K27: 0 | L27: 70 | M27: 0 | N27: 0
A28: SKU006 | B28: Company X | C28: 0 | D28: 0 | E28: 0 | F28: 0 | G28: 0 | H28: 0 | I28: 0 | J28: 0 | K28: 0 | L28: 0 | M28: 0 | N28: 0
A29: SKU006 | B29: Company Y | C29: 0 | D29: 0 | E29: 0 | F29: 0 | G29: 0 | H29: 0 | I29: 0 | J29: 0 | K29: 0 | L29: 0 | M29: 0 | N29: 0
... A37: SKU010 | B37: Company Y | C37: 0 | D37: 0 | E37: 0 | F37: 0 | G37: 0 | H37: 0 | I37: 0 | J37: 0 | K37: 0 | L37: 0 | M37: 0 | N37: 0
A38: TOTAL DEMAND (ALL CHANNELS)
A39: SKU | C39: January | D39: February | E39: March | F39: April | G39: May | H39: June | I39: July | J39: August | K39: September | L39: October | M39: November | N39: December
A40: SKU001 | B40: TOTAL | C40: =C6+C18+C19 -> 15 | D40: =D6+D18+D19 -> 118 | E40: =E6+E18+E19 -> 170 | F40: =F6+F18+F19 -> 22 | G40: =G6+G18+G19 -> 25 | H40: =H6+H18+H19 -> 178 | I40: =I6+I18+I19 -> 230 | J40: =J6+J18+J19 -> 32 | ... N40: =N6+N18+N19 -> 45
A41: SKU002 | B41: TOTAL | C41: =C7+C20+C21 -> 12 | D41: =D7+D20+D21 -> 89 | E41: =E7+E20+E21 -> 116 | F41: =F7+F20+F21 -> 18 | G41: =G7+G20+G21 -> 20 | H41: =H7+H20+H21 -> 122 | I41: =I7+I20+I21 -> 174 | J41: =J7+J20+J21 -> 26 | ... N41: =N7+N20+N21 -> 35
A42: SKU003 | B42: TOTAL | C42: =C8+C22+C23 -> 10 | D42: =D8+D22+D23 -> 72 | E42: =E8+E22+E23 -> 94 | F42: =F8+F22+F23 -> 15 | G42: =G8+G22+G23 -> 17 | H42: =H8+H22+H23 -> 99 | I42: =I8+I22+I23 -> 141 | J42: =J8+J22+J23 -> 23 | ... N42: =N8+N22+N23 -> 32
A43: SKU004 | B43: TOTAL | C43: =C9+C24+C25 -> 8 | D43: =D9+D24+D25 -> 50 | E43: =E9+E24+E25 -> 61 | F43: =F9+F24+F25 -> 13 | G43: =G9+G24+G25 -> 15 | H43: =H9+H24+H25 -> 77 | I43: =I9+I24+I25 -> 99 | J43: =J9+J24+J25 -> 21 | ... N43: =N9+N24+N25 -> 30
A44: SKU005 | B44: TOTAL | C44: =C10+C26+C27 -> 7 | D44: =D10+D26+D27 -> 44 | E44: =E10+E26+E27 -> 50 | F44: =F10+F26+F27 -> 12 | G44: =G10+G26+G27 -> 14 | H44: =H10+H26+H27 -> 71 | I44: =I10+I26+I27 -> 88 | J44: =J10+J26+J27 -> 20 | ... N44: =N10+N26+N27 -> 28
A45: SKU006 | B45: TOTAL | C45: =C11+C28+C29 -> 6 | D45: =D11+D28+D29 -> 8 | E45: =E11+E28+E29 -> 9 | F45: =F11+F28+F29 -> 11 | G45: =G11+G28+G29 -> 13 | H45: =H11+H28+H29 -> 15 | I45: =I11+I28+I29 -> 17 | J45: =J11+J28+J29 -> 19 | ... N45: =N11+N28+N29 -> 27
A46: SKU007 | B46: TOTAL | C46: =C12+C30+C31 -> 50 | D46: =D12+D30+D31 -> 55 | E46: =E12+E30+E31 -> 60 | F46: =F12+F30+F31 -> 65 | G46: =G12+G30+G31 -> 70 | H46: =H12+H30+H31 -> 75 | I46: =I12+I30+I31 -> 80 | J46: =J12+J30+J31 -> 85 | ... N46: =N12+N30+N31 -> 110
A47: SKU008 | B47: TOTAL | C47: =C13+C32+C33 -> 40 | D47: =D13+D32+D33 -> 45 | E47: =E13+E32+E33 -> 50 | F47: =F13+F32+F33 -> 55 | G47: =G13+G32+G33 -> 60 | H47: =H13+H32+H33 -> 65 | I47: =I13+I32+I33 -> 70 | J47: =J13+J32+J33 -> 75 | ... N47: =N13+N32+N33 -> 95
A48: SKU009 | B48: TOTAL | C48: =C14+C34+C35 -> 30 | D48: =D14+D34+D35 -> 35 | E48: =E14+E34+E35 -> 40 | F48: =F14+F34+F35 -> 45 | G48: =G14+G34+G35 -> 50 | H48: =H14+H34+H35 -> 55 | I48: =I14+I34+I35 -> 60 | J48: =J14+J34+J35 -> 65 | ... N48: =N14+N34+N35 -> 85
...

Sheet Inventory Model
A1: INVENTORY MODEL
A2: Real-time inventory tracking with lead-time-aware reorder alerts
A4: SKU | B4: Metric | C4: January | D4: February | E4: March | F4: April | G4: May | H4: June | I4: July | J4: August | K4: September | L4: October | M4: November | N4: December | O4: Status
A5: SKU001 | B5: Beginning Inventory | C5: =Assumptions!H5 -> 250 | D5: =C9 -> 235 | E5: =D9 -> 117 | F5: =E9 -> 0 | G5: =F9 -> 0 | H5: =G9 -> 0 | I5: =H9 -> 0 | J5: =I9 -> 0 | K5: =J9 -> 0 | ... N5: =M9 -> 0
B6: Gross Sales | C6: ='Demand Forecast'!C40 -> 15 | D6: ='Demand Forecast'!D40 -> 118 | E6: ='Demand Forecast'!E40 -> 170 | F6: ='Demand Forecast'!F40 -> 22 | G6: ='Demand Forecast'!G40 -> 25 | H6: ='Demand Forecast'!H40 -> 178 | I6: ='Demand Forecast'!I40 -> 230 | J6: ='Demand Forecast'!J40 -> 32 | ... N6: ='Demand Forecast'!N40 -> 45
B7: Net Position | C7: =C5-C6 -> 235 | D7: =D5-D6 -> 117 | E7: =E5-E6 -> -53 | F7: =F5-F6 -> -22 | G7: =G5-G6 -> -25 | H7: =H5-H6 -> -178 | I7: =I5-I6 -> -230 | J7: =J5-J6 -> -32 | ... N7: =N5-N6 -> -45
B8: Incoming Shipments ⚠️ | C8: 0 | D8: 0 | E8: 0 | F8: 0 | G8: 0 | H8: 0 | I8: 0 | J8: 0 | K8: 0 | L8: 0 | M8: 0 | N8: 0
B9: Ending Inventory | C9: =MAX(0,C7+C8) -> 235 | D9: =MAX(0,D7+D8) -> 117 | E9: =MAX(0,E7+E8) -> 0 | F9: =MAX(0,F7+F8) -> 0 | G9: =MAX(0,G7+G8) -> 0 | H9: =MAX(0,H7+H8) -> 0 | I9: =MAX(0,I7+I8) -> 0 | J9: =MAX(0,J7+J8) -> 0 | ... N9: =MAX(0,N7+N8) -> 0 | O9: =IF(N9<Assumptions!G5,"🚨 REORDER NOW",IF(N9<1.5*Assumptions!G5,"⚠️ ORDER SOON","✅ OK")) -> 🚨 REORDER NOW
B10: Months of Supply | C10: =IFERROR(C9/D6,"-") -> 1.9915254 | D10: =IFERROR(D9/E6,"-") -> 0.68823529 | E10: =IFERROR(E9/F6,"-") -> 0 | F10: =IFERROR(F9/G6,"-") -> 0 | G10: =IFERROR(G9/H6,"-") -> 0 | H10: =IFERROR(H9/I6,"-") -> 0 | I10: =IFERROR(I9/J6,"-") -> 0 | J10: =IFERROR(J9/K6,"-") -> 0 | ... M10: =IFERROR(M9/N6,"-") -> 0 | N10: -
B11: 🚨 Order Alert | C11: {=IF(COLUMN()+Assumptions!F5>14,"",IF(INDIRECT(ADDRESS(ROW()-2,COLUMN()+Assumptions!F5))<Assumptions!G5,"ORDER NOW!",""))} -> ORDER NOW! | D11: {=IF(COLUMN()+Assumptions!F5>14,"",IF(INDIRECT(ADDRESS(ROW()-2,COLUMN()+Assumptions!F5))<Assumptions!G5,"ORDER NOW!",""))} -> ORDER NOW! | E11: {=IF(COLUMN()+Assumptions!F5>14,"",IF(INDIRECT(ADDRESS(ROW()-2,COLUMN()+Assumptions!F5))<Assumptions!G5,"ORDER NOW!",""))} -> ORDER NOW! | F11: {=IF(COLUMN()+Assumptions!F5>14,"",IF(INDIRECT(ADDRESS(ROW()-2,COLUMN()+Assumptions!F5))<Assumptions!G5,"ORDER NOW!",""))} -> ORDER NOW! | G11: {=IF(COLUMN()+Assumptions!F5>14,"",IF(INDIRECT(ADDRESS(ROW()-2,COLUMN()+Assumptions!F5))<Assumptions!G5,"ORDER NOW!",""))} -> ORDER NOW! | H11: {=IF(COLUMN()+Assumptions!F5>14,"",IF(INDIRECT(ADDRESS(ROW()-2,COLUMN()+Assumptions!F5))<Assumptions!G5,"ORDER NOW!",""))} -> ORDER NOW! | I11: {=IF(COLUMN()+Assumptions!F5>14,"",IF(INDIRECT(ADDRESS(ROW()-2,COLUMN()+Assumptions!F5))<Assumptions!G5,"ORDER NOW!",""))} -> ORDER NOW! | J11: {=IF(COLUMN()+Assumptions!F5>14,"",IF(INDIRECT(ADDRESS(ROW()-2,COLUMN()+Assumptions!F5))<Assumptions!G5,"ORDER NOW!",""))} -> ORDER NOW! | K11: {=IF(COLUMN()+Assumptions!F5>14,"",IF(INDIRECT(ADDRESS(ROW()-2,COLUMN()+Assumptions!F5))<Assumptions!G5,"ORDER NOW!",""))} -> ORDER NOW! | L11: {=IF(COLUMN()+Assumptions!F5>14,"",IF(INDIRECT(ADDRESS(ROW()-2,COLUMN()+Assumptions!F5))<Assumptions!G5,"ORDER NOW!",""))} | M11: {=IF(COLUMN()+Assumptions!F5>14,"",IF(INDIRECT(ADDRESS(ROW()-2,COLUMN()+Assumptions!F5))<Assumptions!G5,"ORDER NOW!",""))} | N11: {=IF(COLUMN()+Assumptions!F5>14,"",IF(INDIRECT(ADDRESS(ROW()-2,COLUMN()+Assumptions!F5))<Assumptions!G5,"ORDER NOW!",""))}
B12: Order Qty Needed | C12: {=IF(C11="ORDER NOW!",MAX(Assumptions!I5,Assumptions!G5-INDIRECT(ADDRESS(ROW()-3,COLUMN()+Assumptions!F5))+INDIRECT(ADDRESS(ROW()-6,COLUMN()+Assumptions!F5))),"")} -> 122 | D12: {=IF(D11="ORDER NOW!",MAX(Assumptions!I5,Assumptions!G5-INDIRECT(ADDRESS(ROW()-3,COLUMN()+Assumptions!F5))+INDIRECT(ADDRESS(ROW()-6,COLUMN()+Assumptions!F5))),"")} -> 125 | E12: {=IF(E11="ORDER NOW!",MAX(Assumptions!I5,Assumptions!G5-INDIRECT(ADDRESS(ROW()-3,COLUMN()+Assumptions!F5))+INDIRECT(ADDRESS(ROW()-6,COLUMN()+Assumptions!F5))),"")} -> 278 | F12: {=IF(F11="ORDER NOW!",MAX(Assumptions!I5,Assumptions!G5-INDIRECT(ADDRESS(ROW()-3,COLUMN()+Assumptions!F5))+INDIRECT(ADDRESS(ROW()-6,COLUMN()+Assumptions!F5))),"")} -> 330 | G12: {=IF(G11="ORDER NOW!",MAX(Assumptions!I5,Assumptions!G5-INDIRECT(ADDRESS(ROW()-3,COLUMN()+Assumptions!F5))+INDIRECT(ADDRESS(ROW()-6,COLUMN()+Assumptions!F5))),"")} -> 132 | H12: {=IF(H11="ORDER NOW!",MAX(Assumptions!I5,Assumptions!G5-INDIRECT(ADDRESS(ROW()-3,COLUMN()+Assumptions!F5))+INDIRECT(ADDRESS(ROW()-6,COLUMN()+Assumptions!F5))),"")} -> 135 | I12: {=IF(I11="ORDER NOW!",MAX(Assumptions!I5,Assumptions!G5-INDIRECT(ADDRESS(ROW()-3,COLUMN()+Assumptions!F5))+INDIRECT(ADDRESS(ROW()-6,COLUMN()+Assumptions!F5))),"")} -> 338 | J12: {=IF(J11="ORDER NOW!",MAX(Assumptions!I5,Assumptions!G5-INDIRECT(ADDRESS(ROW()-3,COLUMN()+Assumptions!F5))+INDIRECT(ADDRESS(ROW()-6,COLUMN()+Assumptions!F5))),"")} -> 390 | K12: {=IF(K11="ORDER NOW!",MAX(Assumptions!I5,Assumptions!G5-INDIRECT(ADDRESS(ROW()-3,COLUMN()+Assumptions!F5))+INDIRECT(ADDRESS(ROW()-6,COLUMN()+Assumptions!F5))),"")} -> 145 | L12: {=IF(L11="ORDER NOW!",MAX(Assumptions!I5,Assumptions!G5-INDIRECT(ADDRESS(ROW()-3,COLUMN()+Assumptions!F5))+INDIRECT(ADDRESS(ROW()-6,COLUMN()+Assumptions!F5))),"")} | M12: {=IF(M11="ORDER NOW!",MAX(Assumptions!I5,Assumptions!G5-INDIRECT(ADDRESS(ROW()-3,COLUMN()+Assumptions!F5))+INDIRECT(ADDRESS(ROW()-6,COLUMN()+Assumptions!F5))),"")} | N12: {=IF(N11="ORDER NOW!",MAX(Assumptions!I5,Assumptions!G5-INDIRECT(ADDRESS(ROW()-3,COLUMN()+Assumptions!F5))+INDIRECT(ADDRESS(ROW()-6,COLUMN()+Assumptions!F5))),"")}
A14: SKU002 | B14: Beginning Inventory | C14: =Assumptions!H6 -> 180 | D14: =C18 -> 168 | E14: =D18 -> 79 | F14: =E18 -> 0 | G14: =F18 -> 0 | H14: =G18 -> 0 | I14: =H18 -> 0 | J14: =I18 -> 0 | K14: =J18 -> 0 | ... N14: =M18 -> 0
B15: Gross Sales | C15: ='Demand Forecast'!C41 -> 12 | D15: ='Demand Forecast'!D41 -> 89 | E15: ='Demand Forecast'!E41 -> 116 | F15: ='Demand Forecast'!F41 -> 18 | G15: ='Demand Forecast'!G41 -> 20 | H15: ='Demand Forecast'!H41 -> 122 | I15: ='Demand Forecast'!I41 -> 174 | J15: ='Demand Forecast'!J41 -> 26 | ... N15: ='Demand Forecast'!N41 -> 35
B16: Net Position | C16: =C14-C15 -> 168 | D16: =D14-D15 -> 79 | E16: =E14-E15 -> -37 | F16: =F14-F15 -> -18 | G16: =G14-G15 -> -20 | H16: =H14-H15 -> -122 | I16: =I14-I15 -> -174 | J16: =J14-J15 -> -26 | ... N16: =N14-N15 -> -35
B17: Incoming Shipments ⚠️ | C17: 0 | D17: 0 | E17: 0 | F17: 0 | G17: 0 | H17: 0 | I17: 0 | J17: 0 | K17: 0 | L17: 0 | M17: 0 | N17: 0
B18: Ending Inventory | C18: =MAX(0,C16+C17) -> 168 | D18: =MAX(0,D16+D17) -> 79 | E18: =MAX(0,E16+E17) -> 0 | F18: =MAX(0,F16+F17) -> 0 | G18: =MAX(0,G16+G17) -> 0 | H18: =MAX(0,H16+H17) -> 0 | I18: =MAX(0,I16+I17) -> 0 | J18: =MAX(0,J16+J17) -> 0 | ... N18: =MAX(0,N16+N17) -> 0 | O18: =IF(N18<Assumptions!G6,"🚨 REORDER NOW",IF(N18<1.5*Assumptions!G6,"⚠️ ORDER SOON","✅ OK")) -> 🚨 REORDER NOW
B19: Months of Supply | C19: =IFERROR(C18/D15,"-") -> 1.8876404 | D19: =IFERROR(D18/E15,"-") -> 0.68103448 | E19: =IFERROR(E18/F15,"-") -> 0 | F19: =IFERROR(F18/G15,"-") -> 0 | G19: =IFERROR(G18/H15,"-") -> 0 | H19: =IFERROR(H18/I15,"-") -> 0 | I19: =IFERROR(I18/J15,"-") -> 0 | J19: =IFERROR(J18/K15,"-") -> 0 | ... M19: =IFERROR(M18/N15,"-") -> 0 | N19: -
B20: 🚨 Order Alert | C20: {=IF(COLUMN()+Assumptions!F6>14,"",IF(INDIRECT(ADDRESS(ROW()-2,COLUMN()+Assumptions!F6))<Assumptions!G6,"ORDER NOW!",""))} -> ORDER NOW! | D20: {=IF(COLUMN()+Assumptions!F6>14,"",IF(INDIRECT(ADDRESS(ROW()-2,COLUMN()+Assumptions!F6))<Assumptions!G6,"ORDER NOW!",""))} -> ORDER NOW! | E20: {=IF(COLUMN()+Assumptions!F6>14,"",IF(INDIRECT(ADDRESS(ROW()-2,COLUMN()+Assumptions!F6))<Assumptions!G6,"ORDER NOW!",""))} -> ORDER NOW! | F20: {=IF(COLUMN()+Assumptions!F6>14,"",IF(INDIRECT(ADDRESS(ROW()-2,COLUMN()+Assumptions!F6))<Assumptions!G6,"ORDER NOW!",""))} -> ORDER NOW! | G20: {=IF(COLUMN()+Assumptions!F6>14,"",IF(INDIRECT(ADDRESS(ROW()-2,COLUMN()+Assumptions!F6))<Assumptions!G6,"ORDER NOW!",""))} -> ORDER NOW! | H20: {=IF(COLUMN()+Assumptions!F6>14,"",IF(INDIRECT(ADDRESS(ROW()-2,COLUMN()+Assumptions!F6))<Assumptions!G6,"ORDER NOW!",""))} -> ORDER NOW! | I20: {=IF(COLUMN()+Assumptions!F6>14,"",IF(INDIRECT(ADDRESS(ROW()-2,COLUMN()+Assumptions!F6))<Assumptions!G6,"ORDER NOW!",""))} -> ORDER NOW! | J20: {=IF(COLUMN()+Assumptions!F6>14,"",IF(INDIRECT(ADDRESS(ROW()-2,COLUMN()+Assumptions!F6))<Assumptions!G6,"ORDER NOW!",""))} -> ORDER NOW! | K20: {=IF(COLUMN()+Assumptions!F6>14,"",IF(INDIRECT(ADDRESS(ROW()-2,COLUMN()+Assumptions!F6))<Assumptions!G6,"ORDER NOW!",""))} -> ORDER NOW! | L20: {=IF(COLUMN()+Assumptions!F6>14,"",IF(INDIRECT(ADDRESS(ROW()-2,COLUMN()+Assumptions!F6))<Assumptions!G6,"ORDER NOW!",""))} | M20: {=IF(COLUMN()+Assumptions!F6>14,"",IF(INDIRECT(ADDRESS(ROW()-2,COLUMN()+Assumptions!F6))<Assumptions!G6,"ORDER NOW!",""))} | N20: {=IF(COLUMN()+Assumptions!F6>14,"",IF(INDIRECT(ADDRESS(ROW()-2,COLUMN()+Assumptions!F6))<Assumptions!G6,"ORDER NOW!",""))}
B21: Order Qty Needed | C21: {=IF(C20="ORDER NOW!",MAX(Assumptions!I6,Assumptions!G6-INDIRECT(ADDRESS(ROW()-3,COLUMN()+Assumptions!F6))+INDIRECT(ADDRESS(ROW()-6,COLUMN()+Assumptions!F6))),"")} -> 118 | D21: {=IF(D20="ORDER NOW!",MAX(Assumptions!I6,Assumptions!G6-INDIRECT(ADDRESS(ROW()-3,COLUMN()+Assumptions!F6))+INDIRECT(ADDRESS(ROW()-6,COLUMN()+Assumptions!F6))),"")} -> 120 | E21: {=IF(E20="ORDER NOW!",MAX(Assumptions!I6,Assumptions!G6-INDIRECT(ADDRESS(ROW()-3,COLUMN()+Assumptions!F6))+INDIRECT(ADDRESS(ROW()-6,COLUMN()+Assumptions!F6))),"")} -> 222 | F21: {=IF(F20="ORDER NOW!",MAX(Assumptions!I6,Assumptions!G6-INDIRECT(ADDRESS(ROW()-3,COLUMN()+Assumptions!F6))+INDIRECT(ADDRESS(ROW()-6,COLUMN()+Assumptions!F6))),"")} -> 274 | G21: {=IF(G20="ORDER NOW!",MAX(Assumptions!I6,Assumptions!G6-INDIRECT(ADDRESS(ROW()-3,COLUMN()+Assumptions!F6))+INDIRECT(ADDRESS(ROW()-6,COLUMN()+Assumptions!F6))),"")} -> 126 | H21: {=IF(H20="ORDER NOW!",MAX(Assumptions!I6,Assumptions!G6-INDIRECT(ADDRESS(ROW()-3,COLUMN()+Assumptions!F6))+INDIRECT(ADDRESS(ROW()-6,COLUMN()+Assumptions!F6))),"")} -> 128 | I21: {=IF(I20="ORDER NOW!",MAX(Assumptions!I6,Assumptions!G6-INDIRECT(ADDRESS(ROW()-3,COLUMN()+Assumptions!F6))+INDIRECT(ADDRESS(ROW()-6,COLUMN()+Assumptions!F6))),"")} -> 255 | J21: {=IF(J20="ORDER NOW!",MAX(Assumptions!I6,Assumptions!G6-INDIRECT(ADDRESS(ROW()-3,COLUMN()+Assumptions!F6))+INDIRECT(ADDRESS(ROW()-6,COLUMN()+Assumptions!F6))),"")} -> 332 | K21: {=IF(K20="ORDER NOW!",MAX(Assumptions!I6,Assumptions!G6-INDIRECT(ADDRESS(ROW()-3,COLUMN()+Assumptions!F6))+INDIRECT(ADDRESS(ROW()-6,COLUMN()+Assumptions!F6))),"")} -> 135 | L21: {=IF(L20="ORDER NOW!",MAX(Assumptions!I6,Assumptions!G6-INDIRECT(ADDRESS(ROW()-3,COLUMN()+Assumptions!F6))+INDIRECT(ADDRESS(ROW()-6,COLUMN()+Assumptions!F6))),"")} | M21: {=IF(M20="ORDER NOW!",MAX(Assumptions!I6,Assumptions!G6-INDIRECT(ADDRESS(ROW()-3,COLUMN()+Assumptions!F6))+INDIRECT(ADDRESS(ROW()-6,COLUMN()+Assumptions!F6))),"")} | N21: {=IF(N20="ORDER NOW!",MAX(Assumptions!I6,Assumptions!G6-INDIRECT(ADDRESS(ROW()-3,COLUMN()+Assumptions!F6))+INDIRECT(ADDRESS(ROW()-6,COLUMN()+Assumptions!F6))),"")}
A23: SKU003 | B23: Beginning Inventory | C23: =Assumptions!H7 -> 150 | D23: =C27 -> 140 | E23: =D27 -> 68 | F23: =E27 -> 0 | G23: =F27 -> 0 | H23: =G27 -> 0 | I23: =H27 -> 0 | J23: =I27 -> 0 | K23: =J27 -> 0 | ... N23: =M27 -> 0
B24: Gross Sales | C24: ='Demand Forecast'!C42 -> 10 | D24: ='Demand Forecast'!D42 -> 72 | E24: ='Demand Forecast'!E42 -> 94 | F24: ='Demand Forecast'!F42 -> 15 | G24: ='Demand Forecast'!G42 -> 17 | H24: ='Demand Forecast'!H42 -> 99 | I24: ='Demand Forecast'!I42 -> 141 | J24: ='Demand Forecast'!J42 -> 23 | ... N24: ='Demand Forecast'!N42 -> 32
B25: Net Position | C25: =C23-C24 -> 140 | D25: =D23-D24 -> 68 | E25: =E23-E24 -> -26 | F25: =F23-F24 -> -15 | G25: =G23-G24 -> -17 | H25: =H23-H24 -> -99 | I25: =I23-I24 -> -141 | J25: =J23-J24 -> -23 | ... N25: =N23-N24 -> -32
B26: Incoming Shipments ⚠️ | C26: 0 | D26: 0 | E26: 0 | F26: 0 | G26: 0 | H26: 0 | I26: 0 | J26: 0 | K26: 0 | L26: 0 | M26: 0 | N26: 0
B27: Ending Inventory | C27: =MAX(0,C25+C26) -> 140 | D27: =MAX(0,D25+D26) -> 68 | E27: =MAX(0,E25+E26) -> 0 | F27: =MAX(0,F25+F26) -> 0 | G27: =MAX(0,G25+G26) -> 0 | H27: =MAX(0,H25+H26) -> 0 | I27: =MAX(0,I25+I26) -> 0 | J27: =MAX(0,J25+J26) -> 0 | ... N27: =MAX(0,N25+N26) -> 0 | O27: =IF(N27<Assumptions!G7,"🚨 REORDER NOW",IF(N27<1.5*Assumptions!G7,"⚠️ ORDER SOON","✅ OK")) -> 🚨 REORDER NOW
B28: Months of Supply | C28: =IFERROR(C27/D24,"-") -> 1.9444444 | D28: =IFERROR(D27/E24,"-") -> 0.72340426 | E28: =IFERROR(E27/F24,"-") -> 0 | F28: =IFERROR(F27/G24,"-") -> 0 | G28: =IFERROR(G27/H24,"-") -> 0 | H28: =IFERROR(H27/I24,"-") -> 0 | I28: =IFERROR(I27/J24,"-") -> 0 | J28: =IFERROR(J27/K24,"-") -> 0 | ... M28: =IFERROR(M27/N24,"-") -> 0 | N28: -
B29: 🚨 Order Alert | C29: {=IF(COLUMN()+Assumptions!F7>14,"",IF(INDIRECT(ADDRESS(ROW()-2,COLUMN()+Assumptions!F7))<Assumptions!G7,"ORDER NOW!",""))} -> ORDER NOW! | D29: {=IF(COLUMN()+Assumptions!F7>14,"",IF(INDIRECT(ADDRESS(ROW()-2,COLUMN()+Assumptions!F7))<Assumptions!G7,"ORDER NOW!",""))} -> ORDER NOW! | E29: {=IF(COLUMN()+Assumptions!F7>14,"",IF(INDIRECT(ADDRESS(ROW()-2,COLUMN()+Assumptions!F7))<Assumptions!G7,"ORDER NOW!",""))} -> ORDER NOW! | F29: {=IF(COLUMN()+Assumptions!F7>14,"",IF(INDIRECT(ADDRESS(ROW()-2,COLUMN()+Assumptions!F7))<Assumptions!G7,"ORDER NOW!",""))} -> ORDER NOW! | G29: {=IF(COLUMN()+Assumptions!F7>14,"",IF(INDIRECT(ADDRESS(ROW()-2,COLUMN()+Assumptions!F7))<Assumptions!G7,"ORDER NOW!",""))} -> ORDER NOW! | H29: {=IF(COLUMN()+Assumptions!F7>14,"",IF(INDIRECT(ADDRESS(ROW()-2,COLUMN()+Assumptions!F7))<Assumptions!G7,"ORDER NOW!",""))} -> ORDER NOW! | I29: {=IF(COLUMN()+Assumptions!F7>14,"",IF(INDIRECT(ADDRESS(ROW()-2,COLUMN()+Assumptions!F7))<Assumptions!G7,"ORDER NOW!",""))} -> ORDER NOW! | J29: {=IF(COLUMN()+Assumptions!F7>14,"",IF(INDIRECT(ADDRESS(ROW()-2,COLUMN()+Assumptions!F7))<Assumptions!G7,"ORDER NOW!",""))} -> ORDER NOW! | K29: {=IF(COLUMN()+Assumptions!F7>14,"",IF(INDIRECT(ADDRESS(ROW()-2,COLUMN()+Assumptions!F7))<Assumptions!G7,"ORDER NOW!",""))} -> ORDER NOW! | L29: {=IF(COLUMN()+Assumptions!F7>14,"",IF(INDIRECT(ADDRESS(ROW()-2,COLUMN()+Assumptions!F7))<Assumptions!G7,"ORDER NOW!",""))} | M29: {=IF(COLUMN()+Assumptions!F7>14,"",IF(INDIRECT(ADDRESS(ROW()-2,COLUMN()+Assumptions!F7))<Assumptions!G7,"ORDER NOW!",""))} | N29: {=IF(COLUMN()+Assumptions!F7>14,"",IF(INDIRECT(ADDRESS(ROW()-2,COLUMN()+Assumptions!F7))<Assumptions!G7,"ORDER NOW!",""))}
B30: Order Qty Needed | C30: {=IF(C29="ORDER NOW!",MAX(Assumptions!I7,Assumptions!G7-INDIRECT(ADDRESS(ROW()-3,COLUMN()+Assumptions!F7))+INDIRECT(ADDRESS(ROW()-6,COLUMN()+Assumptions!F7))),"")} -> 95 | D30: {=IF(D29="ORDER NOW!",MAX(Assumptions!I7,Assumptions!G7-INDIRECT(ADDRESS(ROW()-3,COLUMN()+Assumptions!F7))+INDIRECT(ADDRESS(ROW()-6,COLUMN()+Assumptions!F7))),"")} -> 97 | E30: {=IF(E29="ORDER NOW!",MAX(Assumptions!I7,Assumptions!G7-INDIRECT(ADDRESS(ROW()-3,COLUMN()+Assumptions!F7))+INDIRECT(ADDRESS(ROW()-6,COLUMN()+Assumptions!F7))),"")} -> 179 | F30: {=IF(F29="ORDER NOW!",MAX(Assumptions!I7,Assumptions!G7-INDIRECT(ADDRESS(ROW()-3,COLUMN()+Assumptions!F7))+INDIRECT(ADDRESS(ROW()-6,COLUMN()+Assumptions!F7))),"")} -> 221 | G30: {=IF(G29="ORDER NOW!",MAX(Assumptions!I7,Assumptions!G7-INDIRECT(ADDRESS(ROW()-3,COLUMN()+Assumptions!F7))+INDIRECT(ADDRESS(ROW()-6,COLUMN()+Assumptions!F7))),"")} -> 103 | H30: {=IF(H29="ORDER NOW!",MAX(Assumptions!I7,Assumptions!G7-INDIRECT(ADDRESS(ROW()-3,COLUMN()+Assumptions!F7))+INDIRECT(ADDRESS(ROW()-6,COLUMN()+Assumptions!F7))),"")} -> 105 | I30: {=IF(I29="ORDER NOW!",MAX(Assumptions!I7,Assumptions!G7-INDIRECT(ADDRESS(ROW()-3,COLUMN()+Assumptions!F7))+INDIRECT(ADDRESS(ROW()-6,COLUMN()+Assumptions!F7))),"")} -> 207 | J30: {=IF(J29="ORDER NOW!",MAX(Assumptions!I7,Assumptions!G7-INDIRECT(ADDRESS(ROW()-3,COLUMN()+Assumptions!F7))+INDIRECT(ADDRESS(ROW()-6,COLUMN()+Assumptions!F7))),"")} -> 259 | K30: {=IF(K29="ORDER NOW!",MAX(Assumptions!I7,Assumptions!G7-INDIRECT(ADDRESS(ROW()-3,COLUMN()+Assumptions!F7))+INDIRECT(ADDRESS(ROW()-6,COLUMN()+Assumptions!F7))),"")} -> 112 | L30: {=IF(L29="ORDER NOW!",MAX(Assumptions!I7,Assumptions!G7-INDIRECT(ADDRESS(ROW()-3,COLUMN()+Assumptions!F7))+INDIRECT(ADDRESS(ROW()-6,COLUMN()+Assumptions!F7))),"")} | M30: {=IF(M29="ORDER NOW!",MAX(Assumptions!I7,Assumptions!G7-INDIRECT(ADDRESS(ROW()-3,COLUMN()+Assumptions!F7))+INDIRECT(ADDRESS(ROW()-6,COLUMN()+Assumptions!F7))),"")} | N30: {=IF(N29="ORDER NOW!",MAX(Assumptions!I7,Assumptions!G7-INDIRECT(ADDRESS(ROW()-3,COLUMN()+Assumptions!F7))+INDIRECT(ADDRESS(ROW()-6,COLUMN()+Assumptions!F7))),"")}
A32: SKU004 | B32: Beginning Inventory | C32: =Assumptions!H8 -> 120 | D32: =C36 -> 112 | E32: =D36 -> 62 | F32: =E36 -> 1 | G32: =F36 -> 0 | H32: =G36 -> 0 | I32: =H36 -> 0 | J32: =I36 -> 0 | K32: =J36 -> 0 | ... N32: =M36 -> 0
B33: Gross Sales | C33: ='Demand Forecast'!C43 -> 8 | D33: ='Demand Forecast'!D43 -> 50 | E33: ='Demand Forecast'!E43 -> 61 | F33: ='Demand Forecast'!F43 -> 13 | G33: ='Demand Forecast'!G43 -> 15 | H33: ='Demand Forecast'!H43 -> 77 | I33: ='Demand Forecast'!I43 -> 99 | J33: ='Demand Forecast'!J43 -> 21 | ... N33: ='Demand Forecast'!N43 -> 30
B34: Net Position | C34: =C32-C33 -> 112 | D34: =D32-D33 -> 62 | E34: =E32-E33 -> 1 | F34: =F32-F33 -> -12 | G34: =G32-G33 -> -15 | H34: =H32-H33 -> -77 | I34: =I32-I33 -> -99 | J34: =J32-J33 -> -21 | ... N34: =N32-N33 -> -30
B35: Incoming Shipments ⚠️ | C35: 0 | D35: 0 | E35: 0 | F35: 0 | G35: 0 | H35: 0 | I35: 0 | J35: 0 | K35: 0 | L35: 0 | M35: 0 | N35: 0
B36: Ending Inventory | C36: =MAX(0,C34+C35) -> 112 | D36: =MAX(0,D34+D35) -> 62 | E36: =MAX(0,E34+E35) -> 1 | F36: =MAX(0,F34+F35) -> 0 | G36: =MAX(0,G34+G35) -> 0 | H36: =MAX(0,H34+H35) -> 0 | I36: =MAX(0,I34+I35) -> 0 | J36: =MAX(0,J34+J35) -> 0 | ... N36: =MAX(0,N34+N35) -> 0 | O36: =IF(N36<Assumptions!G8,"🚨 REORDER NOW",IF(N36<1.5*Assumptions!G8,"⚠️ ORDER SOON","✅ OK")) -> 🚨 REORDER NOW
B37: Months of Supply | C37: =IFERROR(C36/D33,"-") -> 2.24 | D37: =IFERROR(D36/E33,"-") -> 1.0163934 | E37: =IFERROR(E36/F33,"-") -> 0.076923077 | F37: =IFERROR(F36/G33,"-") -> 0 | G37: =IFERROR(G36/H33,"-") -> 0 | H37: =IFERROR(H36/I33,"-") -> 0 | I37: =IFERROR(I36/J33,"-") -> 0 | J37: =IFERROR(J36/K33,"-") -> 0 | ... M37: =IFERROR(M36/N33,"-") -> 0 | N37: -
B38: 🚨 Order Alert | C38: {=IF(COLUMN()+Assumptions!F8>14,"",IF(INDIRECT(ADDRESS(ROW()-2,COLUMN()+Assumptions!F8))<Assumptions!G8,"ORDER NOW!",""))} -> ORDER NOW! | D38: {=IF(COLUMN()+Assumptions!F8>14,"",IF(INDIRECT(ADDRESS(ROW()-2,COLUMN()+Assumptions!F8))<Assumptions!G8,"ORDER NOW!",""))} -> ORDER NOW! | E38: {=IF(COLUMN()+Assumptions!F8>14,"",IF(INDIRECT(ADDRESS(ROW()-2,COLUMN()+Assumptions!F8))<Assumptions!G8,"ORDER NOW!",""))} -> ORDER NOW! | F38: {=IF(COLUMN()+Assumptions!F8>14,"",IF(INDIRECT(ADDRESS(ROW()-2,COLUMN()+Assumptions!F8))<Assumptions!G8,"ORDER NOW!",""))} -> ORDER NOW! | G38: {=IF(COLUMN()+Assumptions!F8>14,"",IF(INDIRECT(ADDRESS(ROW()-2,COLUMN()+Assumptions!F8))<Assumptions!G8,"ORDER NOW!",""))} -> ORDER NOW! | H38: {=IF(COLUMN()+Assumptions!F8>14,"",IF(INDIRECT(ADDRESS(ROW()-2,COLUMN()+Assumptions!F8))<Assumptions!G8,"ORDER NOW!",""))} -> ORDER NOW! | I38: {=IF(COLUMN()+Assumptions!F8>14,"",IF(INDIRECT(ADDRESS(ROW()-2,COLUMN()+Assumptions!F8))<Assumptions!G8,"ORDER NOW!",""))} -> ORDER NOW! | J38: {=IF(COLUMN()+Assumptions!F8>14,"",IF(INDIRECT(ADDRESS(ROW()-2,COLUMN()+Assumptions!F8))<Assumptions!G8,"ORDER NOW!",""))} -> ORDER NOW! | K38: {=IF(COLUMN()+Assumptions!F8>14,"",IF(INDIRECT(ADDRESS(ROW()-2,COLUMN()+Assumptions!F8))<Assumptions!G8,"ORDER NOW!",""))} -> ORDER NOW! | L38: {=IF(COLUMN()+Assumptions!F8>14,"",IF(INDIRECT(ADDRESS(ROW()-2,COLUMN()+Assumptions!F8))<Assumptions!G8,"ORDER NOW!",""))} | M38: {=IF(COLUMN()+Assumptions!F8>14,"",IF(INDIRECT(ADDRESS(ROW()-2,COLUMN()+Assumptions!F8))<Assumptions!G8,"ORDER NOW!",""))} | N38: {=IF(COLUMN()+Assumptions!F8>14,"",IF(INDIRECT(ADDRESS(ROW()-2,COLUMN()+Assumptions!F8))<Assumptions!G8,"ORDER NOW!",""))}
B39: Order Qty Needed | C39: {=IF(C38="ORDER NOW!",MAX(Assumptions!I8,Assumptions!G8-INDIRECT(ADDRESS(ROW()-3,COLUMN()+Assumptions!F8))+INDIRECT(ADDRESS(ROW()-6,COLUMN()+Assumptions!F8))),"")} -> 93 | D39: {=IF(D38="ORDER NOW!",MAX(Assumptions!I8,Assumptions!G8-INDIRECT(ADDRESS(ROW()-3,COLUMN()+Assumptions!F8))+INDIRECT(ADDRESS(ROW()-6,COLUMN()+Assumptions!F8))),"")} -> 95 | E39: {=IF(E38="ORDER NOW!",MAX(Assumptions!I8,Assumptions!G8-INDIRECT(ADDRESS(ROW()-3,COLUMN()+Assumptions!F8))+INDIRECT(ADDRESS(ROW()-6,COLUMN()+Assumptions!F8))),"")} -> 157 | F39: {=IF(F38="ORDER NOW!",MAX(Assumptions!I8,Assumptions!G8-INDIRECT(ADDRESS(ROW()-3,COLUMN()+Assumptions!F8))+INDIRECT(ADDRESS(ROW()-6,COLUMN()+Assumptions!F8))),"")} -> 179 | G39: {=IF(G38="ORDER NOW!",MAX(Assumptions!I8,Assumptions!G8-INDIRECT(ADDRESS(ROW()-3,COLUMN()+Assumptions!F8))+INDIRECT(ADDRESS(ROW()-6,COLUMN()+Assumptions!F8))),"")} -> 101 | H39: {=IF(H38="ORDER NOW!",MAX(Assumptions!I8,Assumptions!G8-INDIRECT(ADDRESS(ROW()-3,COLUMN()+Assumptions!F8))+INDIRECT(ADDRESS(ROW()-6,COLUMN()+Assumptions!F8))),"")} -> 103 | I39: {=IF(I38="ORDER NOW!",MAX(Assumptions!I8,Assumptions!G8-INDIRECT(ADDRESS(ROW()-3,COLUMN()+Assumptions!F8))+INDIRECT(ADDRESS(ROW()-6,COLUMN()+Assumptions!F8))),"")} -> 180 | J39: {=IF(J38="ORDER NOW!",MAX(Assumptions!I8,Assumptions!G8-INDIRECT(ADDRESS(ROW()-3,COLUMN()+Assumptions!F8))+INDIRECT(ADDRESS(ROW()-6,COLUMN()+Assumptions!F8))),"")} -> 207 | K39: {=IF(K38="ORDER NOW!",MAX(Assumptions!I8,Assumptions!G8-INDIRECT(ADDRESS(ROW()-3,COLUMN()+Assumptions!F8))+INDIRECT(ADDRESS(ROW()-6,COLUMN()+Assumptions!F8))),"")} -> 110 | L39: {=IF(L38="ORDER NOW!",MAX(Assumptions!I8,Assumptions!G8-INDIRECT(ADDRESS(ROW()-3,COLUMN()+Assumptions!F8))+INDIRECT(ADDRESS(ROW()-6,COLUMN()+Assumptions!F8))),"")} | M39: {=IF(M38="ORDER NOW!",MAX(Assumptions!I8,Assumptions!G8-INDIRECT(ADDRESS(ROW()-3,COLUMN()+Assumptions!F8))+INDIRECT(ADDRESS(ROW()-6,COLUMN()+Assumptions!F8))),"")} | N39: {=IF(N38="ORDER NOW!",MAX(Assumptions!I8,Assumptions!G8-INDIRECT(ADDRESS(ROW()-3,COLUMN()+Assumptions!F8))+INDIRECT(ADDRESS(ROW()-6,COLUMN()+Assumptions!F8))),"")}
A41: SKU005 | B41: Beginning Inventory | C41: =Assumptions!H9 -> 110 | D41: =C45 -> 103 | E41: =D45 -> 59 | F41: =E45 -> 9 | G41: =F45 -> 0 | H41: =G45 -> 0 | I41: =H45 -> 0 | J41: =I45 -> 0 | K41: =J45 -> 0 | ... N41: =M45 -> 0
B42: Gross Sales | C42: ='Demand Forecast'!C44 -> 7 | D42: ='Demand Forecast'!D44 -> 44 | E42: ='Demand Forecast'!E44 -> 50 | F42: ='Demand Forecast'!F44 -> 12 | G42: ='Demand Forecast'!G44 -> 14 | H42: ='Demand Forecast'!H44 -> 71 | I42: ='Demand Forecast'!I44 -> 88 | J42: ='Demand Forecast'!J44 -> 20 | ... N42: ='Demand Forecast'!N44 -> 28
B43: Net Position | C43: =C41-C42 -> 103 | D43: =D41-D42 -> 59 | E43: =E41-E42 -> 9 | F43: =F41-F42 -> -3 | G43: =G41-G42 -> -14 | H43: =H41-H42 -> -71 | I43: =I41-I42 -> -88 | J43: =J41-J42 -> -20 | ... N43: =N41-N42 -> -28
B44: Incoming Shipments ⚠️ | C44: 0 | D44: 0 | E44: 0 | F44: 0 | G44: 0 | H44: 0 | I44: 0 | J44: 0 | K44: 0 | L44: 0 | M44: 0 | N44: 0
B45: Ending Inventory | C45: =MAX(0,C43+C44) -> 103 | D45: =MAX(0,D43+D44) -> 59 | E45: =MAX(0,E43+E44) -> 9 | F45: =MAX(0,F43+F44) -> 0 | G45: =MAX(0,G43+G44) -> 0 | H45: =MAX(0,H43+H44) -> 0 | I45: =MAX(0,I43+I44) -> 0 | J45: =MAX(0,J43+J44) -> 0 | ... N45: =MAX(0,N43+N44) -> 0 | O45: =IF(N45<Assumptions!G9,"🚨 REORDER NOW",IF(N45<1.5*Assumptions!G9,"⚠️ ORDER SOON","✅ OK")) -> 🚨 REORDER NOW
...

Sheet Financial Summary
A1: FINANCIAL SUMMARY
A2: Monthly revenue, costs, margins, and cash flow
A4: REVENUE
A5: Line Item | B5: Description | C5: January | D5: February | E5: March | F5: April | G5: May | H5: June | I5: July | J5: August | K5: September | L5: October | M5: November | N5: December
A6: DTC Revenue | B6: (units × DTC price) | C6: =('Demand Forecast'!C6*Assumptions!D5)+('Demand Forecast'!C7*Assumptions!D6)+('Demand Forecast'!C8*Assumptions!D7)+('Demand Forecast'!C9*Assumptions!D8)+('Demand Forecast'!C10*Assumptions!D9)+('Demand Forecast'!C11*Assumptions!D10)+('Demand Forecast'!C12*Assumptions!D11)+('Demand Forecast'!C13*Assumptions!D12)+('Demand Forecast'!C14*Assumptions!D13)+('Demand Forecast'!C15*Assumptions!D14) -> 22609.97 | D6: =('Demand Forecast'!D6*Assumptions!D5)+('Demand Forecast'!D7*Assumptions!D6)+('Demand Forecast'!D8*Assumptions!D7)+('Demand Forecast'!D9*Assumptions!D8)+('Demand Forecast'!D10*Assumptions!D9)+('Demand Forecast'!D11*Assumptions!D10)+('Demand Forecast'!D12*Assumptions!D11)+('Demand Forecast'!D13*Assumptions!D12)+('Demand Forecast'!D14*Assumptions!D13)+('Demand Forecast'!D15*Assumptions!D14) -> 27421.66 | E6: =('Demand Forecast'!E6*Assumptions!D5)+('Demand Forecast'!E7*Assumptions!D6)+('Demand Forecast'!E8*Assumptions!D7)+('Demand Forecast'!E9*Assumptions!D8)+('Demand Forecast'!E10*Assumptions!D9)+('Demand Forecast'!E11*Assumptions!D10)+('Demand Forecast'!E12*Assumptions!D11)+('Demand Forecast'!E13*Assumptions!D12)+('Demand Forecast'!E14*Assumptions!D13)+('Demand Forecast'!E15*Assumptions!D14) -> 30807.4 | F6: =('Demand Forecast'!F6*Assumptions!D5)+('Demand Forecast'!F7*Assumptions!D6)+('Demand Forecast'!F8*Assumptions!D7)+('Demand Forecast'!F9*Assumptions!D8)+('Demand Forecast'!F10*Assumptions!D9)+('Demand Forecast'!F11*Assumptions!D10)+('Demand Forecast'!F12*Assumptions!D11)+('Demand Forecast'!F13*Assumptions!D12)+('Demand Forecast'!F14*Assumptions!D13)+('Demand Forecast'!F15*Assumptions!D14) -> 34931.11 | G6: =('Demand Forecast'!G6*Assumptions!D5)+('Demand Forecast'!G7*Assumptions!D6)+('Demand Forecast'!G8*Assumptions!D7)+('Demand Forecast'!G9*Assumptions!D8)+('Demand Forecast'!G10*Assumptions!D9)+('Demand Forecast'!G11*Assumptions!D10)+('Demand Forecast'!G12*Assumptions!D11)+('Demand Forecast'!G13*Assumptions!D12)+('Demand Forecast'!G14*Assumptions!D13)+('Demand Forecast'!G15*Assumptions!D14) -> 39742.8 | H6: =('Demand Forecast'!H6*Assumptions!D5)+('Demand Forecast'!H7*Assumptions!D6)+('Demand Forecast'!H8*Assumptions!D7)+('Demand Forecast'!H9*Assumptions!D8)+('Demand Forecast'!H10*Assumptions!D9)+('Demand Forecast'!H11*Assumptions!D10)+('Demand Forecast'!H12*Assumptions!D11)+('Demand Forecast'!H13*Assumptions!D12)+('Demand Forecast'!H14*Assumptions!D13)+('Demand Forecast'!H15*Assumptions!D14) -> 44604.48 | I6: =('Demand Forecast'!I6*Assumptions!D5)+('Demand Forecast'!I7*Assumptions!D6)+('Demand Forecast'!I8*Assumptions!D7)+('Demand Forecast'!I9*Assumptions!D8)+('Demand Forecast'!I10*Assumptions!D9)+('Demand Forecast'!I11*Assumptions!D10)+('Demand Forecast'!I12*Assumptions!D11)+('Demand Forecast'!I13*Assumptions!D12)+('Demand Forecast'!I14*Assumptions!D13)+('Demand Forecast'!I15*Assumptions!D14) -> 49122.17 | J6: =('Demand Forecast'!J6*Assumptions!D5)+('Demand Forecast'!J7*Assumptions!D6)+('Demand Forecast'!J8*Assumptions!D7)+('Demand Forecast'!J9*Assumptions!D8)+('Demand Forecast'!J10*Assumptions!D9)+('Demand Forecast'!J11*Assumptions!D10)+('Demand Forecast'!J12*Assumptions!D11)+('Demand Forecast'!J13*Assumptions!D12)+('Demand Forecast'!J14*Assumptions!D13)+('Demand Forecast'!J15*Assumptions!D14) -> 53639.86 | K6: =('Demand Forecast'!K6*Assumptions!D5)+('Demand Forecast'!K7*Assumptions!D6)+('Demand Forecast'!K8*Assumptions!D7)+('Demand Forecast'!K9*Assumptions!D8)+('Demand Forecast'!K10*Assumptions!D9)+('Demand Forecast'!K11*Assumptions!D10)+('Demand Forecast'!K12*Assumptions!D11)+('Demand Forecast'!K13*Assumptions!D12)+('Demand Forecast'!K14*Assumptions!D13)+('Demand Forecast'!K15*Assumptions!D14) -> 58501.54 | L6: =('Demand Forecast'!L6*Assumptions!D5)+('Demand Forecast'!L7*Assumptions!D6)+('Demand Forecast'!L8*Assumptions!D7)+('Demand Forecast'!L9*Assumptions!D8)+('Demand Forecast'!L10*Assumptions!D9)+('Demand Forecast'!L11*Assumptions!D10)+('Demand Forecast'!L12*Assumptions!D11)+('Demand Forecast'!L13*Assumptions!D12)+('Demand Forecast'!L14*Assumptions!D13)+('Demand Forecast'!L15*Assumptions!D14) -> 63363.22 | M6: =('Demand Forecast'!M6*Assumptions!D5)+('Demand Forecast'!M7*Assumptions!D6)+('Demand Forecast'!M8*Assumptions!D7)+('Demand Forecast'!M9*Assumptions!D8)+('Demand Forecast'!M10*Assumptions!D9)+('Demand Forecast'!M11*Assumptions!D10)+('Demand Forecast'!M12*Assumptions!D11)+('Demand Forecast'!M13*Assumptions!D12)+('Demand Forecast'!M14*Assumptions!D13)+('Demand Forecast'!M15*Assumptions!D14) -> 67880.91 | N6: =('Demand Forecast'!N6*Assumptions!D5)+('Demand Forecast'!N7*Assumptions!D6)+('Demand Forecast'!N8*Assumptions!D7)+('Demand Forecast'!N9*Assumptions!D8)+('Demand Forecast'!N10*Assumptions!D9)+('Demand Forecast'!N11*Assumptions!D10)+('Demand Forecast'!N12*Assumptions!D11)+('Demand Forecast'!N13*Assumptions!D12)+('Demand Forecast'!N14*Assumptions!D13)+('Demand Forecast'!N15*Assumptions!D14) -> 74557.48
A7: Wholesale Revenue | B7: (units × wholesale price) | C7: =('Demand Forecast'!C18*Assumptions!E5)+('Demand Forecast'!C19*Assumptions!E5)+('Demand Forecast'!C20*Assumptions!E6)+('Demand Forecast'!C21*Assumptions!E6)+('Demand Forecast'!C22*Assumptions!E7)+('Demand Forecast'!C23*Assumptions!E7)+('Demand Forecast'!C24*Assumptions!E8)+('Demand Forecast'!C25*Assumptions!E8)+('Demand Forecast'!C26*Assumptions!E9)+('Demand Forecast'!C27*Assumptions!E9)+('Demand Forecast'!C28*Assumptions!E10)+('Demand Forecast'!C29*Assumptions!E10)+('Demand Forecast'!C30*Assumptions!E11)+('Demand Forecast'!C31*Assumptions!E11)+('Demand Forecast'!C32*Assumptions!E12)+('Demand Forecast'!C33*Assumptions!E12)+('Demand Forecast'!C34*Assumptions!E13)+('Demand Forecast'!C35*Assumptions!E13)+('Demand Forecast'!C36*Assumptions!E14)+('Demand Forecast'!C37*Assumptions!E14) -> 0 | D7: =('Demand Forecast'!D18*Assumptions!E5)+('Demand Forecast'!D19*Assumptions!E5)+('Demand Forecast'!D20*Assumptions!E6)+('Demand Forecast'!D21*Assumptions!E6)+('Demand Forecast'!D22*Assumptions!E7)+('Demand Forecast'!D23*Assumptions!E7)+('Demand Forecast'!D24*Assumptions!E8)+('Demand Forecast'!D25*Assumptions!E8)+('Demand Forecast'!D26*Assumptions!E9)+('Demand Forecast'!D27*Assumptions!E9)+('Demand Forecast'!D28*Assumptions!E10)+('Demand Forecast'!D29*Assumptions!E10)+('Demand Forecast'!D30*Assumptions!E11)+('Demand Forecast'!D31*Assumptions!E11)+('Demand Forecast'!D32*Assumptions!E12)+('Demand Forecast'!D33*Assumptions!E12)+('Demand Forecast'!D34*Assumptions!E13)+('Demand Forecast'!D35*Assumptions!E13)+('Demand Forecast'!D36*Assumptions!E14)+('Demand Forecast'!D37*Assumptions!E14) -> 85425 | E7: =('Demand Forecast'!E18*Assumptions!E5)+('Demand Forecast'!E19*Assumptions!E5)+('Demand Forecast'!E20*Assumptions!E6)+('Demand Forecast'!E21*Assumptions!E6)+('Demand Forecast'!E22*Assumptions!E7)+('Demand Forecast'!E23*Assumptions!E7)+('Demand Forecast'!E24*Assumptions!E8)+('Demand Forecast'!E25*Assumptions!E8)+('Demand Forecast'!E26*Assumptions!E9)+('Demand Forecast'!E27*Assumptions!E9)+('Demand Forecast'!E28*Assumptions!E10)+('Demand Forecast'!E29*Assumptions!E10)+('Demand Forecast'!E30*Assumptions!E11)+('Demand Forecast'!E31*Assumptions!E11)+('Demand Forecast'!E32*Assumptions!E12)+('Demand Forecast'!E33*Assumptions!E12)+('Demand Forecast'!E34*Assumptions!E13)+('Demand Forecast'!E35*Assumptions!E13)+('Demand Forecast'!E36*Assumptions!E14)+('Demand Forecast'!E37*Assumptions!E14) -> 115700 | F7: =('Demand Forecast'!F18*Assumptions!E5)+('Demand Forecast'!F19*Assumptions!E5)+('Demand Forecast'!F20*Assumptions!E6)+('Demand Forecast'!F21*Assumptions!E6)+('Demand Forecast'!F22*Assumptions!E7)+('Demand Forecast'!F23*Assumptions!E7)+('Demand Forecast'!F24*Assumptions!E8)+('Demand Forecast'!F25*Assumptions!E8)+('Demand Forecast'!F26*Assumptions!E9)+('Demand Forecast'!F27*Assumptions!E9)+('Demand Forecast'!F28*Assumptions!E10)+('Demand Forecast'!F29*Assumptions!E10)+('Demand Forecast'!F30*Assumptions!E11)+('Demand Forecast'!F31*Assumptions!E11)+('Demand Forecast'!F32*Assumptions!E12)+('Demand Forecast'!F33*Assumptions!E12)+('Demand Forecast'!F34*Assumptions!E13)+('Demand Forecast'!F35*Assumptions!E13)+('Demand Forecast'!F36*Assumptions!E14)+('Demand Forecast'!F37*Assumptions!E14) -> 0 | G7: =('Demand Forecast'!G18*Assumptions!E5)+('Demand Forecast'!G19*Assumptions!E5)+('Demand Forecast'!G20*Assumptions!E6)+('Demand Forecast'!G21*Assumptions!E6)+('Demand Forecast'!G22*Assumptions!E7)+('Demand Forecast'!G23*Assumptions!E7)+('Demand Forecast'!G24*Assumptions!E8)+('Demand Forecast'!G25*Assumptions!E8)+('Demand Forecast'!G26*Assumptions!E9)+('Demand Forecast'!G27*Assumptions!E9)+('Demand Forecast'!G28*Assumptions!E10)+('Demand Forecast'!G29*Assumptions!E10)+('Demand Forecast'!G30*Assumptions!E11)+('Demand Forecast'!G31*Assumptions!E11)+('Demand Forecast'!G32*Assumptions!E12)+('Demand Forecast'!G33*Assumptions!E12)+('Demand Forecast'!G34*Assumptions!E13)+('Demand Forecast'!G35*Assumptions!E13)+('Demand Forecast'!G36*Assumptions!E14)+('Demand Forecast'!G37*Assumptions!E14) -> 0 | H7: =('Demand Forecast'!H18*Assumptions!E5)+('Demand Forecast'!H19*Assumptions!E5)+('Demand Forecast'!H20*Assumptions!E6)+('Demand Forecast'!H21*Assumptions!E6)+('Demand Forecast'!H22*Assumptions!E7)+('Demand Forecast'!H23*Assumptions!E7)+('Demand Forecast'!H24*Assumptions!E8)+('Demand Forecast'!H25*Assumptions!E8)+('Demand Forecast'!H26*Assumptions!E9)+('Demand Forecast'!H27*Assumptions!E9)+('Demand Forecast'!H28*Assumptions!E10)+('Demand Forecast'!H29*Assumptions!E10)+('Demand Forecast'!H30*Assumptions!E11)+('Demand Forecast'!H31*Assumptions!E11)+('Demand Forecast'!H32*Assumptions!E12)+('Demand Forecast'!H33*Assumptions!E12)+('Demand Forecast'!H34*Assumptions!E13)+('Demand Forecast'!H35*Assumptions!E13)+('Demand Forecast'!H36*Assumptions!E14)+('Demand Forecast'!H37*Assumptions!E14) -> 122650 | I7: =('Demand Forecast'!I18*Assumptions!E5)+('Demand Forecast'!I19*Assumptions!E5)+('Demand Forecast'!I20*Assumptions!E6)+('Demand Forecast'!I21*Assumptions!E6)+('Demand Forecast'!I22*Assumptions!E7)+('Demand Forecast'!I23*Assumptions!E7)+('Demand Forecast'!I24*Assumptions!E8)+('Demand Forecast'!I25*Assumptions!E8)+('Demand Forecast'!I26*Assumptions!E9)+('Demand Forecast'!I27*Assumptions!E9)+('Demand Forecast'!I28*Assumptions!E10)+('Demand Forecast'!I29*Assumptions!E10)+('Demand Forecast'!I30*Assumptions!E11)+('Demand Forecast'!I31*Assumptions!E11)+('Demand Forecast'!I32*Assumptions!E12)+('Demand Forecast'!I33*Assumptions!E12)+('Demand Forecast'!I34*Assumptions!E13)+('Demand Forecast'!I35*Assumptions!E13)+('Demand Forecast'!I36*Assumptions!E14)+('Demand Forecast'!I37*Assumptions!E14) -> 170850 | J7: =('Demand Forecast'!J18*Assumptions!E5)+('Demand Forecast'!J19*Assumptions!E5)+('Demand Forecast'!J20*Assumptions!E6)+('Demand Forecast'!J21*Assumptions!E6)+('Demand Forecast'!J22*Assumptions!E7)+('Demand Forecast'!J23*Assumptions!E7)+('Demand Forecast'!J24*Assumptions!E8)+('Demand Forecast'!J25*Assumptions!E8)+('Demand Forecast'!J26*Assumptions!E9)+('Demand Forecast'!J27*Assumptions!E9)+('Demand Forecast'!J28*Assumptions!E10)+('Demand Forecast'!J29*Assumptions!E10)+('Demand Forecast'!J30*Assumptions!E11)+('Demand Forecast'!J31*Assumptions!E11)+('Demand Forecast'!J32*Assumptions!E12)+('Demand Forecast'!J33*Assumptions!E12)+('Demand Forecast'!J34*Assumptions!E13)+('Demand Forecast'!J35*Assumptions!E13)+('Demand Forecast'!J36*Assumptions!E14)+('Demand Forecast'!J37*Assumptions!E14) -> 0 | K7: =('Demand Forecast'!K18*Assumptions!E5)+('Demand Forecast'!K19*Assumptions!E5)+('Demand Forecast'!K20*Assumptions!E6)+('Demand Forecast'!K21*Assumptions!E6)+('Demand Forecast'!K22*Assumptions!E7)+('Demand Forecast'!K23*Assumptions!E7)+('Demand Forecast'!K24*Assumptions!E8)+('Demand Forecast'!K25*Assumptions!E8)+('Demand Forecast'!K26*Assumptions!E9)+('Demand Forecast'!K27*Assumptions!E9)+('Demand Forecast'!K28*Assumptions!E10)+('Demand Forecast'!K29*Assumptions!E10)+('Demand Forecast'!K30*Assumptions!E11)+('Demand Forecast'!K31*Assumptions!E11)+('Demand Forecast'!K32*Assumptions!E12)+('Demand Forecast'!K33*Assumptions!E12)+('Demand Forecast'!K34*Assumptions!E13)+('Demand Forecast'!K35*Assumptions!E13)+('Demand Forecast'!K36*Assumptions!E14)+('Demand Forecast'!K37*Assumptions!E14) -> 0 | L7: =('Demand Forecast'!L18*Assumptions!E5)+('Demand Forecast'!L19*Assumptions!E5)+('Demand Forecast'!L20*Assumptions!E6)+('Demand Forecast'!L21*Assumptions!E6)+('Demand Forecast'!L22*Assumptions!E7)+('Demand Forecast'!L23*Assumptions!E7)+('Demand Forecast'!L24*Assumptions!E8)+('Demand Forecast'!L25*Assumptions!E8)+('Demand Forecast'!L26*Assumptions!E9)+('Demand Forecast'!L27*Assumptions!E9)+('Demand Forecast'!L28*Assumptions!E10)+('Demand Forecast'!L29*Assumptions!E10)+('Demand Forecast'!L30*Assumptions!E11)+('Demand Forecast'!L31*Assumptions!E11)+('Demand Forecast'!L32*Assumptions!E12)+('Demand Forecast'!L33*Assumptions!E12)+('Demand Forecast'!L34*Assumptions!E13)+('Demand Forecast'!L35*Assumptions!E13)+('Demand Forecast'!L36*Assumptions!E14)+('Demand Forecast'!L37*Assumptions!E14) -> 157100 | M7: =('Demand Forecast'!M18*Assumptions!E5)+('Demand Forecast'!M19*Assumptions!E5)+('Demand Forecast'!M20*Assumptions!E6)+('Demand Forecast'!M21*Assumptions!E6)+('Demand Forecast'!M22*Assumptions!E7)+('Demand Forecast'!M23*Assumptions!E7)+('Demand Forecast'!M24*Assumptions!E8)+('Demand Forecast'!M25*Assumptions!E8)+('Demand Forecast'!M26*Assumptions!E9)+('Demand Forecast'!M27*Assumptions!E9)+('Demand Forecast'!M28*Assumptions!E10)+('Demand Forecast'!M29*Assumptions!E10)+('Demand Forecast'!M30*Assumptions!E11)+('Demand Forecast'!M31*Assumptions!E11)+('Demand Forecast'!M32*Assumptions!E12)+('Demand Forecast'!M33*Assumptions!E12)+('Demand Forecast'!M34*Assumptions!E13)+('Demand Forecast'!M35*Assumptions!E13)+('Demand Forecast'!M36*Assumptions!E14)+('Demand Forecast'!M37*Assumptions!E14) -> 217700 | N7: =('Demand Forecast'!N18*Assumptions!E5)+('Demand Forecast'!N19*Assumptions!E5)+('Demand Forecast'!N20*Assumptions!E6)+('Demand Forecast'!N21*Assumptions!E6)+('Demand Forecast'!N22*Assumptions!E7)+('Demand Forecast'!N23*Assumptions!E7)+('Demand Forecast'!N24*Assumptions!E8)+('Demand Forecast'!N25*Assumptions!E8)+('Demand Forecast'!N26*Assumptions!E9)+('Demand Forecast'!N27*Assumptions!E9)+('Demand Forecast'!N28*Assumptions!E10)+('Demand Forecast'!N29*Assumptions!E10)+('Demand Forecast'!N30*Assumptions!E11)+('Demand Forecast'!N31*Assumptions!E11)+('Demand Forecast'!N32*Assumptions!E12)+('Demand Forecast'!N33*Assumptions!E12)+('Demand Forecast'!N34*Assumptions!E13)+('Demand Forecast'!N35*Assumptions!E13)+('Demand Forecast'!N36*Assumptions!E14)+('Demand Forecast'!N37*Assumptions!E14) -> 0
A8: Total Revenue | C8: =C6+C7 -> 22609.97 | D8: =D6+D7 -> 112846.66 | E8: =E6+E7 -> 146507.4 | F8: =F6+F7 -> 34931.11 | G8: =G6+G7 -> 39742.8 | H8: =H6+H7 -> 167254.48 | I8: =I6+I7 -> 219972.17 | J8: =J6+J7 -> 53639.86 | ... N8: =N6+N7 -> 74557.48
A10: COST OF GOODS SOLD
A11: Line Item | B11: Description | C11: January | D11: February | E11: March | F11: April | G11: May | H11: June | I11: July | J11: August | K11: September | L11: October | M11: November | N11: December
A12: Total Units Sold | B12: (all channels) | C12: ='Demand Forecast'!C40+'Demand Forecast'!C41+'Demand Forecast'!C42+'Demand Forecast'!C43+'Demand Forecast'!C44+'Demand Forecast'!C45+'Demand Forecast'!C46+'Demand Forecast'!C47+'Demand Forecast'!C48+'Demand Forecast'!C49 -> 203 | D12: ='Demand Forecast'!D40+'Demand Forecast'!D41+'Demand Forecast'!D42+'Demand Forecast'!D43+'Demand Forecast'!D44+'Demand Forecast'!D45+'Demand Forecast'!D46+'Demand Forecast'!D47+'Demand Forecast'!D48+'Demand Forecast'!D49 -> 544 | E12: ='Demand Forecast'!E40+'Demand Forecast'!E41+'Demand Forecast'!E42+'Demand Forecast'!E43+'Demand Forecast'!E44+'Demand Forecast'!E45+'Demand Forecast'!E46+'Demand Forecast'!E47+'Demand Forecast'!E48+'Demand Forecast'!E49 -> 680 | F12: ='Demand Forecast'!F40+'Demand Forecast'!F41+'Demand Forecast'!F42+'Demand Forecast'!F43+'Demand Forecast'!F44+'Demand Forecast'!F45+'Demand Forecast'!F46+'Demand Forecast'!F47+'Demand Forecast'!F48+'Demand Forecast'!F49 -> 289 | G12: ='Demand Forecast'!G40+'Demand Forecast'!G41+'Demand Forecast'!G42+'Demand Forecast'!G43+'Demand Forecast'!G44+'Demand Forecast'!G45+'Demand Forecast'!G46+'Demand Forecast'!G47+'Demand Forecast'!G48+'Demand Forecast'!G49 -> 320 | H12: ='Demand Forecast'!H40+'Demand Forecast'!H41+'Demand Forecast'!H42+'Demand Forecast'!H43+'Demand Forecast'!H44+'Demand Forecast'!H45+'Demand Forecast'!H46+'Demand Forecast'!H47+'Demand Forecast'!H48+'Demand Forecast'!H49 -> 797 | I12: ='Demand Forecast'!I40+'Demand Forecast'!I41+'Demand Forecast'!I42+'Demand Forecast'!I43+'Demand Forecast'!I44+'Demand Forecast'!I45+'Demand Forecast'!I46+'Demand Forecast'!I47+'Demand Forecast'!I48+'Demand Forecast'!I49 -> 1003 | J12: ='Demand Forecast'!J40+'Demand Forecast'!J41+'Demand Forecast'!J42+'Demand Forecast'!J43+'Demand Forecast'!J44+'Demand Forecast'!J45+'Demand Forecast'!J46+'Demand Forecast'!J47+'Demand Forecast'!J48+'Demand Forecast'!J49 -> 414 | ... N12: ='Demand Forecast'!N40+'Demand Forecast'!N41+'Demand Forecast'!N42+'Demand Forecast'!N43+'Demand Forecast'!N44+'Demand Forecast'!N45+'Demand Forecast'!N46+'Demand Forecast'!N47+'Demand Forecast'!N48+'Demand Forecast'!N49 -> 552
A13: COGS | B13: (units × unit cost) | C13: =('Demand Forecast'!C40*Assumptions!C5)+('Demand Forecast'!C41*Assumptions!C6)+('Demand Forecast'!C42*Assumptions!C7)+('Demand Forecast'!C43*Assumptions!C8)+('Demand Forecast'!C44*Assumptions!C9)+('Demand Forecast'!C45*Assumptions!C10)+('Demand Forecast'!C46*Assumptions!C11)+('Demand Forecast'!C47*Assumptions!C12)+('Demand Forecast'!C48*Assumptions!C13)+('Demand Forecast'!C49*Assumptions!C14) -> 8225 | D13: =('Demand Forecast'!D40*Assumptions!C5)+('Demand Forecast'!D41*Assumptions!C6)+('Demand Forecast'!D42*Assumptions!C7)+('Demand Forecast'!D43*Assumptions!C8)+('Demand Forecast'!D44*Assumptions!C9)+('Demand Forecast'!D45*Assumptions!C10)+('Demand Forecast'!D46*Assumptions!C11)+('Demand Forecast'!D47*Assumptions!C12)+('Demand Forecast'!D48*Assumptions!C13)+('Demand Forecast'!D49*Assumptions!C14) -> 47332.5 | E13: =('Demand Forecast'!E40*Assumptions!C5)+('Demand Forecast'!E41*Assumptions!C6)+('Demand Forecast'!E42*Assumptions!C7)+('Demand Forecast'!E43*Assumptions!C8)+('Demand Forecast'!E44*Assumptions!C9)+('Demand Forecast'!E45*Assumptions!C10)+('Demand Forecast'!E46*Assumptions!C11)+('Demand Forecast'!E47*Assumptions!C12)+('Demand Forecast'!E48*Assumptions!C13)+('Demand Forecast'!E49*Assumptions!C14) -> 61775 | F13: =('Demand Forecast'!F40*Assumptions!C5)+('Demand Forecast'!F41*Assumptions!C6)+('Demand Forecast'!F42*Assumptions!C7)+('Demand Forecast'!F43*Assumptions!C8)+('Demand Forecast'!F44*Assumptions!C9)+('Demand Forecast'!F45*Assumptions!C10)+('Demand Forecast'!F46*Assumptions!C11)+('Demand Forecast'!F47*Assumptions!C12)+('Demand Forecast'!F48*Assumptions!C13)+('Demand Forecast'!F49*Assumptions!C14) -> 12667.5 | G13: =('Demand Forecast'!G40*Assumptions!C5)+('Demand Forecast'!G41*Assumptions!C6)+('Demand Forecast'!G42*Assumptions!C7)+('Demand Forecast'!G43*Assumptions!C8)+('Demand Forecast'!G44*Assumptions!C9)+('Demand Forecast'!G45*Assumptions!C10)+('Demand Forecast'!G46*Assumptions!C11)+('Demand Forecast'!G47*Assumptions!C12)+('Demand Forecast'!G48*Assumptions!C13)+('Demand Forecast'!G49*Assumptions!C14) -> 14400 | H13: =('Demand Forecast'!H40*Assumptions!C5)+('Demand Forecast'!H41*Assumptions!C6)+('Demand Forecast'!H42*Assumptions!C7)+('Demand Forecast'!H43*Assumptions!C8)+('Demand Forecast'!H44*Assumptions!C9)+('Demand Forecast'!H45*Assumptions!C10)+('Demand Forecast'!H46*Assumptions!C11)+('Demand Forecast'!H47*Assumptions!C12)+('Demand Forecast'!H48*Assumptions!C13)+('Demand Forecast'!H49*Assumptions!C14) -> 69832.5 | I13: =('Demand Forecast'!I40*Assumptions!C5)+('Demand Forecast'!I41*Assumptions!C6)+('Demand Forecast'!I42*Assumptions!C7)+('Demand Forecast'!I43*Assumptions!C8)+('Demand Forecast'!I44*Assumptions!C9)+('Demand Forecast'!I45*Assumptions!C10)+('Demand Forecast'!I46*Assumptions!C11)+('Demand Forecast'!I47*Assumptions!C12)+('Demand Forecast'!I48*Assumptions!C13)+('Demand Forecast'!I49*Assumptions!C14) -> 92545 | J13: =('Demand Forecast'!J40*Assumptions!C5)+('Demand Forecast'!J41*Assumptions!C6)+('Demand Forecast'!J42*Assumptions!C7)+('Demand Forecast'!J43*Assumptions!C8)+('Demand Forecast'!J44*Assumptions!C9)+('Demand Forecast'!J45*Assumptions!C10)+('Demand Forecast'!J46*Assumptions!C11)+('Demand Forecast'!J47*Assumptions!C12)+('Demand Forecast'!J48*Assumptions!C13)+('Demand Forecast'!J49*Assumptions!C14) -> 19432.5 | K13: =('Demand Forecast'!K40*Assumptions!C5)+('Demand Forecast'!K41*Assumptions!C6)+('Demand Forecast'!K42*Assumptions!C7)+('Demand Forecast'!K43*Assumptions!C8)+('Demand Forecast'!K44*Assumptions!C9)+('Demand Forecast'!K45*Assumptions!C10)+('Demand Forecast'!K46*Assumptions!C11)+('Demand Forecast'!K47*Assumptions!C12)+('Demand Forecast'!K48*Assumptions!C13)+('Demand Forecast'!K49*Assumptions!C14) -> 21190 | L13: =('Demand Forecast'!L40*Assumptions!C5)+('Demand Forecast'!L41*Assumptions!C6)+('Demand Forecast'!L42*Assumptions!C7)+('Demand Forecast'!L43*Assumptions!C8)+('Demand Forecast'!L44*Assumptions!C9)+('Demand Forecast'!L45*Assumptions!C10)+('Demand Forecast'!L46*Assumptions!C11)+('Demand Forecast'!L47*Assumptions!C12)+('Demand Forecast'!L48*Assumptions!C13)+('Demand Forecast'!L49*Assumptions!C14) -> 91697.5 | M13: =('Demand Forecast'!M40*Assumptions!C5)+('Demand Forecast'!M41*Assumptions!C6)+('Demand Forecast'!M42*Assumptions!C7)+('Demand Forecast'!M43*Assumptions!C8)+('Demand Forecast'!M44*Assumptions!C9)+('Demand Forecast'!M45*Assumptions!C10)+('Demand Forecast'!M46*Assumptions!C11)+('Demand Forecast'!M47*Assumptions!C12)+('Demand Forecast'!M48*Assumptions!C13)+('Demand Forecast'!M49*Assumptions!C14) -> 119835 | N13: =('Demand Forecast'!N40*Assumptions!C5)+('Demand Forecast'!N41*Assumptions!C6)+('Demand Forecast'!N42*Assumptions!C7)+('Demand Forecast'!N43*Assumptions!C8)+('Demand Forecast'!N44*Assumptions!C9)+('Demand Forecast'!N45*Assumptions!C10)+('Demand Forecast'!N46*Assumptions!C11)+('Demand Forecast'!N47*Assumptions!C12)+('Demand Forecast'!N48*Assumptions!C13)+('Demand Forecast'!N49*Assumptions!C14) -> 26985
A14: Gross Profit | C14: =C8-C13 -> 14384.97 | D14: =D8-D13 -> 65514.16 | E14: =E8-E13 -> 84732.4 | F14: =F8-F13 -> 22263.61 | G14: =G8-G13 -> 25342.8 | H14: =H8-H13 -> 97421.98 | I14: =I8-I13 -> 127427.17 | J14: =J8-J13 -> 34207.36 | ... N14: =N8-N13 -> 47572.48
A15: Gross Margin % | C15: =IFERROR(C14/C8,0) -> 0.63622243 | D15: =IFERROR(D14/D8,0) -> 0.58055914 | E15: =IFERROR(E14/E8,0) -> 0.57834894 | F15: =IFERROR(F14/F8,0) -> 0.63735764 | G15: =IFERROR(G14/G8,0) -> 0.63767022 | H15: =IFERROR(H14/H8,0) -> 0.58247755 | I15: =IFERROR(I14/I8,0) -> 0.57928769 | J15: =IFERROR(J14/J8,0) -> 0.63772277 | ... N15: =IFERROR(N14/N8,0) -> 0.63806448
A17: CASH FLOW
A18: Line Item | B18: Description | C18: January | D18: February | E18: March | F18: April | G18: May | H18: June | I18: July | J18: August | K18: September | L18: October | M18: November | N18: December
A19: Cash Inflow | B19: (from sales) | C19: =C8 -> 22609.97 | D19: =D8 -> 112846.66 | E19: =E8 -> 146507.4 | F19: =F8 -> 34931.11 | G19: =G8 -> 39742.8 | H19: =H8 -> 167254.48 | I19: =I8 -> 219972.17 | J19: =J8 -> 53639.86 | ... N19: =N8 -> 74557.48
